ffi008: Uncaught exception ghc-internal:GHC.Internal.Exception.ErrorCall:

this is an error
CallStack (from HasCallStack):
  error, called at ffi008.hs:12:12 in main:Main

HasCallStack backtrace:
  collectBacktraces, called at libraries/ghc-internal/src/GHC/Internal/Exception.hs:92:13 in ghc-internal:GHC.Internal.Exception
  toExceptionWithBacktrace, called at libraries/ghc-internal/src/GHC/Internal/Exception.hs:127:5 in ghc-internal:GHC.Internal.Exception
  error, called at ffi008.hs:12:12 in main:Main

