T19288: Uncaught exception ghc-internal:GHC.Internal.Exception.ErrorCall:

No more bug!

HasCallStack backtrace:
  error, called at T19288.hs:25:27 in main:Main

