T13330: Uncaught exception ghc-internal:GHC.Internal.Exception.ErrorCall:

Successful exception

HasCallStack backtrace:
  collectBacktraces, called at libraries/ghc-internal/src/GHC/Internal/Exception.hs:91:13 in ghc-internal:GHC.Internal.Exception
  toExceptionWithBacktrace, called at libraries/ghc-internal/src/GHC/Internal/Exception.hs:118:5 in ghc-internal:GHC.Internal.Exception
  error, called at T13330.hs:5:16 in main:Main

